[2024-02-09T20:02:09.268+0000] {taskinstance.py:1956} INFO - Dependencies all met for dep_context=non-requeueable deps ti=<TaskInstance: weather_dag.transform_load_weather_data_to_S3 scheduled__2024-02-09T19:30:00+00:00 [queued]>
[2024-02-09T20:02:09.283+0000] {taskinstance.py:1956} INFO - Dependencies all met for dep_context=requeueable deps ti=<TaskInstance: weather_dag.transform_load_weather_data_to_S3 scheduled__2024-02-09T19:30:00+00:00 [queued]>
[2024-02-09T20:02:09.284+0000] {taskinstance.py:2170} INFO - Starting attempt 2 of 3
[2024-02-09T20:02:09.306+0000] {taskinstance.py:2191} INFO - Executing <Task(PythonOperator): transform_load_weather_data_to_S3> on 2024-02-09 19:30:00+00:00
[2024-02-09T20:02:09.313+0000] {standard_task_runner.py:60} INFO - Started process 970 to run task
[2024-02-09T20:02:09.320+0000] {standard_task_runner.py:87} INFO - Running: ['***', 'tasks', 'run', 'weather_dag', 'transform_load_weather_data_to_S3', 'scheduled__2024-02-09T19:30:00+00:00', '--job-id', '47', '--raw', '--subdir', 'DAGS_FOLDER/Weather_dag.py', '--cfg-path', '/tmp/tmpbozq3am7']
[2024-02-09T20:02:09.324+0000] {standard_task_runner.py:88} INFO - Job 47: Subtask transform_load_weather_data_to_S3
[2024-02-09T20:02:09.420+0000] {task_command.py:423} INFO - Running <TaskInstance: weather_dag.transform_load_weather_data_to_S3 scheduled__2024-02-09T19:30:00+00:00 [running]> on host 67eb7739a33c
[2024-02-09T20:02:09.565+0000] {taskinstance.py:2480} INFO - Exporting env vars: AIRFLOW_CTX_DAG_OWNER='stellar' AIRFLOW_CTX_DAG_ID='weather_dag' AIRFLOW_CTX_TASK_ID='transform_load_weather_data_to_S3' AIRFLOW_CTX_EXECUTION_DATE='2024-02-09T19:30:00+00:00' AIRFLOW_CTX_TRY_NUMBER='2' AIRFLOW_CTX_DAG_RUN_ID='scheduled__2024-02-09T19:30:00+00:00'
[2024-02-09T20:02:09.569+0000] {taskinstance.py:2698} ERROR - Task failed with exception
Traceback (most recent call last):
  File "/home/airflow/.local/lib/python3.8/site-packages/airflow/models/taskinstance.py", line 433, in _execute_task
    result = execute_callable(context=context, **execute_callable_kwargs)
  File "/home/airflow/.local/lib/python3.8/site-packages/airflow/operators/python.py", line 199, in execute
    return_value = self.execute_callable()
  File "/home/airflow/.local/lib/python3.8/site-packages/airflow/operators/python.py", line 216, in execute_callable
    return self.python_callable(*self.op_args, **self.op_kwargs)
TypeError: transform_load_data() missing 2 required positional arguments: 'WEATHER_API_URL' and 'S3_URI'
[2024-02-09T20:02:09.585+0000] {taskinstance.py:1138} INFO - Marking task as UP_FOR_RETRY. dag_id=weather_dag, task_id=transform_load_weather_data_to_S3, execution_date=20240209T193000, start_date=20240209T200209, end_date=20240209T200209
[2024-02-09T20:02:09.606+0000] {standard_task_runner.py:107} ERROR - Failed to execute job 47 for task transform_load_weather_data_to_S3 (transform_load_data() missing 2 required positional arguments: 'WEATHER_API_URL' and 'S3_URI'; 970)
[2024-02-09T20:02:09.654+0000] {local_task_job_runner.py:234} INFO - Task exited with return code 1
[2024-02-09T20:02:09.685+0000] {taskinstance.py:3280} INFO - 0 downstream tasks scheduled from follow-on schedule check
