[2024-02-11T09:59:18.946+0000] {taskinstance.py:1956} INFO - Dependencies all met for dep_context=non-requeueable deps ti=<TaskInstance: test_redshift_dag.transfer_s3_to_redshift manual__2024-02-11T09:48:43.206022+00:00 [queued]>
[2024-02-11T09:59:18.961+0000] {taskinstance.py:1956} INFO - Dependencies all met for dep_context=requeueable deps ti=<TaskInstance: test_redshift_dag.transfer_s3_to_redshift manual__2024-02-11T09:48:43.206022+00:00 [queued]>
[2024-02-11T09:59:18.962+0000] {taskinstance.py:2170} INFO - Starting attempt 2 of 3
[2024-02-11T09:59:18.987+0000] {taskinstance.py:2191} INFO - Executing <Task(S3ToRedshiftOperator): transfer_s3_to_redshift> on 2024-02-11 09:48:43.206022+00:00
[2024-02-11T09:59:18.997+0000] {standard_task_runner.py:60} INFO - Started process 62 to run task
[2024-02-11T09:59:19.002+0000] {standard_task_runner.py:87} INFO - Running: ['***', 'tasks', 'run', 'test_redshift_dag', 'transfer_s3_to_redshift', 'manual__2024-02-11T09:48:43.206022+00:00', '--job-id', '38', '--raw', '--subdir', 'DAGS_FOLDER/s3 _to_redshift.py', '--cfg-path', '/tmp/tmp71o1aujo']
[2024-02-11T09:59:19.007+0000] {standard_task_runner.py:88} INFO - Job 38: Subtask transfer_s3_to_redshift
[2024-02-11T09:59:19.118+0000] {task_command.py:423} INFO - Running <TaskInstance: test_redshift_dag.transfer_s3_to_redshift manual__2024-02-11T09:48:43.206022+00:00 [running]> on host 35f4ee28a87c
[2024-02-11T09:59:19.284+0000] {taskinstance.py:2480} INFO - Exporting env vars: AIRFLOW_CTX_DAG_OWNER='stellar' AIRFLOW_CTX_DAG_ID='test_redshift_dag' AIRFLOW_CTX_TASK_ID='transfer_s3_to_redshift' AIRFLOW_CTX_EXECUTION_DATE='2024-02-11T09:48:43.206022+00:00' AIRFLOW_CTX_TRY_NUMBER='2' AIRFLOW_CTX_DAG_RUN_ID='manual__2024-02-11T09:48:43.206022+00:00'
[2024-02-11T09:59:19.306+0000] {base.py:83} INFO - Using connection ID 's3_dev_conn' for task execution.
[2024-02-11T09:59:19.317+0000] {base.py:83} INFO - Using connection ID 's3_dev_conn' for task execution.
[2024-02-11T09:59:19.318+0000] {connection_wrapper.py:378} INFO - AWS Connection (conn_id='s3_dev_conn', conn_type='aws') credentials retrieved from login and password.
[2024-02-11T09:59:19.348+0000] {s3_to_redshift.py:192} INFO - Executing COPY command...
[2024-02-11T09:59:19.361+0000] {base.py:83} INFO - Using connection ID 'redshift_default' for task execution.
[2024-02-11T09:59:41.239+0000] {taskinstance.py:2698} ERROR - Task failed with exception
Traceback (most recent call last):
  File "/home/airflow/.local/lib/python3.8/site-packages/redshift_connector/core.py", line 626, in __init__
    self._usock.connect(hostport)
ConnectionRefusedError: [Errno 111] Connection refused

During handling of the above exception, another exception occurred:

Traceback (most recent call last):
  File "/home/airflow/.local/lib/python3.8/site-packages/airflow/models/taskinstance.py", line 433, in _execute_task
    result = execute_callable(context=context, **execute_callable_kwargs)
  File "/home/airflow/.local/lib/python3.8/site-packages/airflow/providers/amazon/aws/transfers/s3_to_redshift.py", line 196, in execute
    redshift_hook.run(sql, autocommit=self.autocommit)
  File "/home/airflow/.local/lib/python3.8/site-packages/airflow/providers/common/sql/hooks/sql.py", line 391, in run
    with closing(self.get_conn()) as conn:
  File "/home/airflow/.local/lib/python3.8/site-packages/airflow/providers/amazon/aws/hooks/redshift_sql.py", line 200, in get_conn
    return redshift_connector.connect(**conn_kwargs)
  File "/home/airflow/.local/lib/python3.8/site-packages/redshift_connector/__init__.py", line 376, in connect
    return Connection(
  File "/home/airflow/.local/lib/python3.8/site-packages/redshift_connector/core.py", line 689, in __init__
    raise InterfaceError("communication error", e)
redshift_connector.error.InterfaceError: ('communication error', ConnectionRefusedError(111, 'Connection refused'))
[2024-02-11T09:59:41.253+0000] {taskinstance.py:1138} INFO - Marking task as UP_FOR_RETRY. dag_id=test_redshift_dag, task_id=transfer_s3_to_redshift, execution_date=20240211T094843, start_date=20240211T095918, end_date=20240211T095941
[2024-02-11T09:59:41.284+0000] {standard_task_runner.py:107} ERROR - Failed to execute job 38 for task transfer_s3_to_redshift (('communication error', ConnectionRefusedError(111, 'Connection refused')); 62)
[2024-02-11T09:59:41.320+0000] {local_task_job_runner.py:234} INFO - Task exited with return code 1
[2024-02-11T09:59:41.369+0000] {taskinstance.py:3280} INFO - 0 downstream tasks scheduled from follow-on schedule check
