[2024-02-26T22:19:57.483+0000] {taskinstance.py:1956} INFO - Dependencies all met for dep_context=non-requeueable deps ti=<TaskInstance: weather_dag.create_snowflake_external_stage manual__2024-02-26T22:19:23.421504+00:00 [queued]>
[2024-02-26T22:19:57.504+0000] {taskinstance.py:1956} INFO - Dependencies all met for dep_context=requeueable deps ti=<TaskInstance: weather_dag.create_snowflake_external_stage manual__2024-02-26T22:19:23.421504+00:00 [queued]>
[2024-02-26T22:19:57.505+0000] {taskinstance.py:2170} INFO - Starting attempt 1 of 3
[2024-02-26T22:19:57.532+0000] {taskinstance.py:2191} INFO - Executing <Task(SnowflakeOperator): create_snowflake_external_stage> on 2024-02-26 22:19:23.421504+00:00
[2024-02-26T22:19:57.542+0000] {standard_task_runner.py:60} INFO - Started process 212 to run task
[2024-02-26T22:19:57.549+0000] {standard_task_runner.py:87} INFO - Running: ['***', 'tasks', 'run', 'weather_dag', 'create_snowflake_external_stage', 'manual__2024-02-26T22:19:23.421504+00:00', '--job-id', '20', '--raw', '--subdir', 'DAGS_FOLDER/Weather_dag.py', '--cfg-path', '/tmp/tmp6mylwnss']
[2024-02-26T22:19:57.552+0000] {standard_task_runner.py:88} INFO - Job 20: Subtask create_snowflake_external_stage
[2024-02-26T22:19:57.673+0000] {task_command.py:423} INFO - Running <TaskInstance: weather_dag.create_snowflake_external_stage manual__2024-02-26T22:19:23.421504+00:00 [running]> on host 5d25474dd79a
[2024-02-26T22:19:57.845+0000] {taskinstance.py:2480} INFO - Exporting env vars: AIRFLOW_CTX_DAG_OWNER='stellar' AIRFLOW_CTX_DAG_ID='weather_dag' AIRFLOW_CTX_TASK_ID='create_snowflake_external_stage' AIRFLOW_CTX_EXECUTION_DATE='2024-02-26T22:19:23.421504+00:00' AIRFLOW_CTX_TRY_NUMBER='1' AIRFLOW_CTX_DAG_RUN_ID='manual__2024-02-26T22:19:23.421504+00:00'
[2024-02-26T22:19:57.848+0000] {sql.py:276} INFO - Executing: 
                    CREATE OR REPLACE STAGE s3_stage
                        URL = "s3://bucket-weather-data/current_weather_data_portland_26022024221936.csv"
                        credentials=(aws_key_id=aws_access_key aws_secret_key=aws_secret_access);
                
            
[2024-02-26T22:19:57.868+0000] {base.py:83} INFO - Using connection ID 'conn_id_snowflake' for task execution.
[2024-02-26T22:19:57.884+0000] {base.py:83} INFO - Using connection ID 'conn_id_snowflake' for task execution.
[2024-02-26T22:19:57.886+0000] {connection.py:370} INFO - Snowflake Connector for Python Version: 3.6.0, Python Version: 3.8.18, Platform: Linux-5.15.133.1-microsoft-standard-WSL2-x86_64-with-glibc2.34
[2024-02-26T22:19:57.888+0000] {connection.py:1171} INFO - This connection is in OCSP Fail Open Mode. TLS Certificates would be checked for validity and revocation status. Any other Certificate Revocation related exceptions or OCSP Responder failures would be disregarded in favor of connectivity.
[2024-02-26T22:19:58.297+0000] {cursor.py:1028} INFO - query: [ALTER SESSION SET autocommit=False]
[2024-02-26T22:19:58.390+0000] {cursor.py:1041} INFO - query execution done
[2024-02-26T22:19:58.392+0000] {cursor.py:1205} INFO - Number of results in first chunk: 1
[2024-02-26T22:19:58.394+0000] {sql.py:450} INFO - Running statement: CREATE OR REPLACE STAGE s3_stage
                        URL = "s3://bucket-weather-data/current_weather_data_portland_26022024221936.csv"
                        credentials=(aws_key_id=aws_access_key aws_secret_key=aws_secret_access);, parameters: None
[2024-02-26T22:19:58.395+0000] {cursor.py:1028} INFO - query: [CREATE OR REPLACE STAGE s3_stage URL = "s3://bucket-weather-data/current_weather...]
[2024-02-26T22:19:58.541+0000] {cursor.py:1041} INFO - query execution done
[2024-02-26T22:19:58.554+0000] {connection.py:718} INFO - closed
[2024-02-26T22:19:58.611+0000] {connection.py:724} INFO - No async queries seem to be running, deleting session
[2024-02-26T22:19:58.672+0000] {taskinstance.py:2698} ERROR - Task failed with exception
Traceback (most recent call last):
  File "/home/airflow/.local/lib/python3.8/site-packages/airflow/models/taskinstance.py", line 433, in _execute_task
    result = execute_callable(context=context, **execute_callable_kwargs)
  File "/home/airflow/.local/lib/python3.8/site-packages/airflow/providers/common/sql/operators/sql.py", line 282, in execute
    output = hook.run(
  File "/home/airflow/.local/lib/python3.8/site-packages/airflow/providers/snowflake/hooks/snowflake.py", line 388, in run
    self._run_command(cur, sql_statement, parameters)
  File "/home/airflow/.local/lib/python3.8/site-packages/airflow/providers/common/sql/hooks/sql.py", line 455, in _run_command
    cur.execute(sql_statement)
  File "/home/airflow/.local/lib/python3.8/site-packages/snowflake/connector/cursor.py", line 1132, in execute
    Error.errorhandler_wrapper(self.connection, self, error_class, errvalue)
  File "/home/airflow/.local/lib/python3.8/site-packages/snowflake/connector/errors.py", line 290, in errorhandler_wrapper
    handed_over = Error.hand_to_other_handler(
  File "/home/airflow/.local/lib/python3.8/site-packages/snowflake/connector/errors.py", line 345, in hand_to_other_handler
    cursor.errorhandler(connection, cursor, error_class, error_value)
  File "/home/airflow/.local/lib/python3.8/site-packages/snowflake/connector/errors.py", line 221, in default_errorhandler
    raise error_class(
snowflake.connector.errors.ProgrammingError: 001008 (22023): 01b29e1b-3201-0126-0000-000805ce50a9: SQL compilation error:
invalid value [aws_access_key] for parameter 'aws_key_id'
[2024-02-26T22:19:58.687+0000] {taskinstance.py:1138} INFO - Marking task as UP_FOR_RETRY. dag_id=weather_dag, task_id=create_snowflake_external_stage, execution_date=20240226T221923, start_date=20240226T221957, end_date=20240226T221958
[2024-02-26T22:19:58.714+0000] {standard_task_runner.py:107} ERROR - Failed to execute job 20 for task create_snowflake_external_stage (001008 (22023): 01b29e1b-3201-0126-0000-000805ce50a9: SQL compilation error:
invalid value [aws_access_key] for parameter 'aws_key_id'; 212)
[2024-02-26T22:19:58.766+0000] {local_task_job_runner.py:234} INFO - Task exited with return code 1
[2024-02-26T22:19:58.828+0000] {taskinstance.py:3280} INFO - 0 downstream tasks scheduled from follow-on schedule check
