[2024-02-12T15:39:06.542+0000] {taskinstance.py:1956} INFO - Dependencies all met for dep_context=non-requeueable deps ti=<TaskInstance: weather_dag.transform_load_weather_data_to_S3 manual__2024-02-12T15:31:45.587046+00:00 [queued]>
[2024-02-12T15:39:06.562+0000] {taskinstance.py:1956} INFO - Dependencies all met for dep_context=requeueable deps ti=<TaskInstance: weather_dag.transform_load_weather_data_to_S3 manual__2024-02-12T15:31:45.587046+00:00 [queued]>
[2024-02-12T15:39:06.563+0000] {taskinstance.py:2170} INFO - Starting attempt 4 of 5
[2024-02-12T15:39:06.584+0000] {taskinstance.py:2191} INFO - Executing <Task(PythonOperator): transform_load_weather_data_to_S3> on 2024-02-12 15:31:45.587046+00:00
[2024-02-12T15:39:06.592+0000] {standard_task_runner.py:60} INFO - Started process 211 to run task
[2024-02-12T15:39:06.598+0000] {standard_task_runner.py:87} INFO - Running: ['***', 'tasks', 'run', 'weather_dag', 'transform_load_weather_data_to_S3', 'manual__2024-02-12T15:31:45.587046+00:00', '--job-id', '69', '--raw', '--subdir', 'DAGS_FOLDER/Weather_dag.py', '--cfg-path', '/tmp/tmpafjp9ee_']
[2024-02-12T15:39:06.600+0000] {standard_task_runner.py:88} INFO - Job 69: Subtask transform_load_weather_data_to_S3
[2024-02-12T15:39:06.672+0000] {task_command.py:423} INFO - Running <TaskInstance: weather_dag.transform_load_weather_data_to_S3 manual__2024-02-12T15:31:45.587046+00:00 [running]> on host f6c6a9bbd38e
[2024-02-12T15:39:06.793+0000] {taskinstance.py:2480} INFO - Exporting env vars: AIRFLOW_CTX_DAG_OWNER='stellar' AIRFLOW_CTX_DAG_ID='weather_dag' AIRFLOW_CTX_TASK_ID='transform_load_weather_data_to_S3' AIRFLOW_CTX_EXECUTION_DATE='2024-02-12T15:31:45.587046+00:00' AIRFLOW_CTX_TRY_NUMBER='4' AIRFLOW_CTX_DAG_RUN_ID='manual__2024-02-12T15:31:45.587046+00:00'
[2024-02-12T15:39:07.371+0000] {taskinstance.py:2698} ERROR - Task failed with exception
Traceback (most recent call last):
  File "/home/airflow/.local/lib/python3.8/site-packages/airflow/models/taskinstance.py", line 433, in _execute_task
    result = execute_callable(context=context, **execute_callable_kwargs)
  File "/home/airflow/.local/lib/python3.8/site-packages/airflow/operators/python.py", line 199, in execute
    return_value = self.execute_callable()
  File "/home/airflow/.local/lib/python3.8/site-packages/airflow/operators/python.py", line 216, in execute_callable
    return self.python_callable(*self.op_args, **self.op_kwargs)
  File "/opt/airflow/dags/Weather_dag.py", line 68, in transform_load_data
    s3_client.put_object(Bucket=bucket_name, Key=object_key, Body=csv_data)
  File "/home/airflow/.local/lib/python3.8/site-packages/botocore/client.py", line 553, in _api_call
    return self._make_api_call(operation_name, kwargs)
  File "/home/airflow/.local/lib/python3.8/site-packages/botocore/client.py", line 1009, in _make_api_call
    raise error_class(parsed_response, operation_name)
botocore.exceptions.ClientError: An error occurred (InvalidAccessKeyId) when calling the PutObject operation: The AWS Access Key Id you provided does not exist in our records.
[2024-02-12T15:39:07.397+0000] {taskinstance.py:1138} INFO - Marking task as UP_FOR_RETRY. dag_id=weather_dag, task_id=transform_load_weather_data_to_S3, execution_date=20240212T153145, start_date=20240212T153906, end_date=20240212T153907
[2024-02-12T15:39:07.418+0000] {standard_task_runner.py:107} ERROR - Failed to execute job 69 for task transform_load_weather_data_to_S3 (An error occurred (InvalidAccessKeyId) when calling the PutObject operation: The AWS Access Key Id you provided does not exist in our records.; 211)
[2024-02-12T15:39:07.455+0000] {local_task_job_runner.py:234} INFO - Task exited with return code 1
[2024-02-12T15:39:07.481+0000] {taskinstance.py:3280} INFO - 0 downstream tasks scheduled from follow-on schedule check
