[2024-02-12T15:37:25.525+0000] {taskinstance.py:1956} INFO - Dependencies all met for dep_context=non-requeueable deps ti=<TaskInstance: weather_dag.transform_load_weather_data_to_S3 scheduled__2024-02-12T15:00:00+00:00 [queued]>
[2024-02-12T15:37:25.540+0000] {taskinstance.py:1956} INFO - Dependencies all met for dep_context=requeueable deps ti=<TaskInstance: weather_dag.transform_load_weather_data_to_S3 scheduled__2024-02-12T15:00:00+00:00 [queued]>
[2024-02-12T15:37:25.541+0000] {taskinstance.py:2170} INFO - Starting attempt 3 of 3
[2024-02-12T15:37:25.562+0000] {taskinstance.py:2191} INFO - Executing <Task(PythonOperator): transform_load_weather_data_to_S3> on 2024-02-12 15:00:00+00:00
[2024-02-12T15:37:25.572+0000] {standard_task_runner.py:60} INFO - Started process 178 to run task
[2024-02-12T15:37:25.578+0000] {standard_task_runner.py:87} INFO - Running: ['***', 'tasks', 'run', 'weather_dag', 'transform_load_weather_data_to_S3', 'scheduled__2024-02-12T15:00:00+00:00', '--job-id', '66', '--raw', '--subdir', 'DAGS_FOLDER/Weather_dag.py', '--cfg-path', '/tmp/tmp39mj2_yg']
[2024-02-12T15:37:25.580+0000] {standard_task_runner.py:88} INFO - Job 66: Subtask transform_load_weather_data_to_S3
[2024-02-12T15:37:25.658+0000] {task_command.py:423} INFO - Running <TaskInstance: weather_dag.transform_load_weather_data_to_S3 scheduled__2024-02-12T15:00:00+00:00 [running]> on host f6c6a9bbd38e
[2024-02-12T15:37:25.806+0000] {taskinstance.py:2480} INFO - Exporting env vars: AIRFLOW_CTX_DAG_OWNER='stellar' AIRFLOW_CTX_DAG_ID='weather_dag' AIRFLOW_CTX_TASK_ID='transform_load_weather_data_to_S3' AIRFLOW_CTX_EXECUTION_DATE='2024-02-12T15:00:00+00:00' AIRFLOW_CTX_TRY_NUMBER='3' AIRFLOW_CTX_DAG_RUN_ID='scheduled__2024-02-12T15:00:00+00:00'
[2024-02-12T15:37:26.345+0000] {taskinstance.py:2698} ERROR - Task failed with exception
Traceback (most recent call last):
  File "/home/airflow/.local/lib/python3.8/site-packages/airflow/models/taskinstance.py", line 433, in _execute_task
    result = execute_callable(context=context, **execute_callable_kwargs)
  File "/home/airflow/.local/lib/python3.8/site-packages/airflow/operators/python.py", line 199, in execute
    return_value = self.execute_callable()
  File "/home/airflow/.local/lib/python3.8/site-packages/airflow/operators/python.py", line 216, in execute_callable
    return self.python_callable(*self.op_args, **self.op_kwargs)
  File "/opt/airflow/dags/Weather_dag.py", line 68, in transform_load_data
    s3_client.put_object(Bucket=bucket_name, Key=object_key, Body=csv_data)
  File "/home/airflow/.local/lib/python3.8/site-packages/botocore/client.py", line 553, in _api_call
    return self._make_api_call(operation_name, kwargs)
  File "/home/airflow/.local/lib/python3.8/site-packages/botocore/client.py", line 1009, in _make_api_call
    raise error_class(parsed_response, operation_name)
botocore.exceptions.ClientError: An error occurred (InvalidAccessKeyId) when calling the PutObject operation: The AWS Access Key Id you provided does not exist in our records.
[2024-02-12T15:37:26.362+0000] {taskinstance.py:1138} INFO - Marking task as FAILED. dag_id=weather_dag, task_id=transform_load_weather_data_to_S3, execution_date=20240212T150000, start_date=20240212T153725, end_date=20240212T153726
[2024-02-12T15:37:26.380+0000] {standard_task_runner.py:107} ERROR - Failed to execute job 66 for task transform_load_weather_data_to_S3 (An error occurred (InvalidAccessKeyId) when calling the PutObject operation: The AWS Access Key Id you provided does not exist in our records.; 178)
[2024-02-12T15:37:26.394+0000] {local_task_job_runner.py:234} INFO - Task exited with return code 1
[2024-02-12T15:37:26.417+0000] {taskinstance.py:3280} INFO - 0 downstream tasks scheduled from follow-on schedule check
