[2024-02-12T21:06:53.903+0000] {taskinstance.py:1956} INFO - Dependencies all met for dep_context=non-requeueable deps ti=<TaskInstance: weather_dag.transform_load_weather_data_to_S3 manual__2024-02-12T21:06:45.688131+00:00 [queued]>
[2024-02-12T21:06:53.918+0000] {taskinstance.py:1956} INFO - Dependencies all met for dep_context=requeueable deps ti=<TaskInstance: weather_dag.transform_load_weather_data_to_S3 manual__2024-02-12T21:06:45.688131+00:00 [queued]>
[2024-02-12T21:06:53.919+0000] {taskinstance.py:2170} INFO - Starting attempt 1 of 3
[2024-02-12T21:06:53.938+0000] {taskinstance.py:2191} INFO - Executing <Task(PythonOperator): transform_load_weather_data_to_S3> on 2024-02-12 21:06:45.688131+00:00
[2024-02-12T21:06:53.949+0000] {standard_task_runner.py:60} INFO - Started process 229 to run task
[2024-02-12T21:06:53.956+0000] {standard_task_runner.py:87} INFO - Running: ['***', 'tasks', 'run', 'weather_dag', 'transform_load_weather_data_to_S3', 'manual__2024-02-12T21:06:45.688131+00:00', '--job-id', '6', '--raw', '--subdir', 'DAGS_FOLDER/Weather_dag.py', '--cfg-path', '/tmp/tmpqq1bpcoy']
[2024-02-12T21:06:53.960+0000] {standard_task_runner.py:88} INFO - Job 6: Subtask transform_load_weather_data_to_S3
[2024-02-12T21:06:54.053+0000] {task_command.py:423} INFO - Running <TaskInstance: weather_dag.transform_load_weather_data_to_S3 manual__2024-02-12T21:06:45.688131+00:00 [running]> on host 3bd3b2605e24
[2024-02-12T21:06:54.246+0000] {taskinstance.py:2480} INFO - Exporting env vars: AIRFLOW_CTX_DAG_OWNER='stellar' AIRFLOW_CTX_DAG_ID='weather_dag' AIRFLOW_CTX_TASK_ID='transform_load_weather_data_to_S3' AIRFLOW_CTX_EXECUTION_DATE='2024-02-12T21:06:45.688131+00:00' AIRFLOW_CTX_TRY_NUMBER='1' AIRFLOW_CTX_DAG_RUN_ID='manual__2024-02-12T21:06:45.688131+00:00'
[2024-02-12T21:06:54.569+0000] {taskinstance.py:2698} ERROR - Task failed with exception
Traceback (most recent call last):
  File "/home/airflow/.local/lib/python3.8/site-packages/airflow/models/taskinstance.py", line 433, in _execute_task
    result = execute_callable(context=context, **execute_callable_kwargs)
  File "/home/airflow/.local/lib/python3.8/site-packages/airflow/operators/python.py", line 199, in execute
    return_value = self.execute_callable()
  File "/home/airflow/.local/lib/python3.8/site-packages/airflow/operators/python.py", line 216, in execute_callable
    return self.python_callable(*self.op_args, **self.op_kwargs)
  File "/opt/airflow/dags/Weather_dag.py", line 70, in transform_load_data
    dt_string = "current_weather_data_portland_" + dt_string
UnboundLocalError: local variable 'dt_string' referenced before assignment
[2024-02-12T21:06:54.593+0000] {taskinstance.py:1138} INFO - Marking task as UP_FOR_RETRY. dag_id=weather_dag, task_id=transform_load_weather_data_to_S3, execution_date=20240212T210645, start_date=20240212T210653, end_date=20240212T210654
[2024-02-12T21:06:54.617+0000] {standard_task_runner.py:107} ERROR - Failed to execute job 6 for task transform_load_weather_data_to_S3 (local variable 'dt_string' referenced before assignment; 229)
[2024-02-12T21:06:54.651+0000] {local_task_job_runner.py:234} INFO - Task exited with return code 1
[2024-02-12T21:06:54.701+0000] {taskinstance.py:3280} INFO - 0 downstream tasks scheduled from follow-on schedule check
