[2024-02-09T18:29:36.904+0000] {taskinstance.py:1956} INFO - Dependencies all met for dep_context=non-requeueable deps ti=<TaskInstance: weather_dag.transform_load_weather_data_to_S3 manual__2024-02-09T18:24:38.941675+00:00 [queued]>
[2024-02-09T18:29:36.921+0000] {taskinstance.py:1956} INFO - Dependencies all met for dep_context=requeueable deps ti=<TaskInstance: weather_dag.transform_load_weather_data_to_S3 manual__2024-02-09T18:24:38.941675+00:00 [queued]>
[2024-02-09T18:29:36.922+0000] {taskinstance.py:2170} INFO - Starting attempt 3 of 3
[2024-02-09T18:29:36.970+0000] {taskinstance.py:2191} INFO - Executing <Task(PythonOperator): transform_load_weather_data_to_S3> on 2024-02-09 18:24:38.941675+00:00
[2024-02-09T18:29:36.982+0000] {standard_task_runner.py:60} INFO - Started process 53 to run task
[2024-02-09T18:29:36.989+0000] {standard_task_runner.py:87} INFO - Running: ['***', 'tasks', 'run', 'weather_dag', 'transform_load_weather_data_to_S3', 'manual__2024-02-09T18:24:38.941675+00:00', '--job-id', '22', '--raw', '--subdir', 'DAGS_FOLDER/Weather_dag.py', '--cfg-path', '/tmp/tmpr58nyye0']
[2024-02-09T18:29:36.992+0000] {standard_task_runner.py:88} INFO - Job 22: Subtask transform_load_weather_data_to_S3
[2024-02-09T18:29:37.079+0000] {task_command.py:423} INFO - Running <TaskInstance: weather_dag.transform_load_weather_data_to_S3 manual__2024-02-09T18:24:38.941675+00:00 [running]> on host 67eb7739a33c
[2024-02-09T18:29:37.224+0000] {taskinstance.py:2480} INFO - Exporting env vars: AIRFLOW_CTX_DAG_OWNER='stellar' AIRFLOW_CTX_DAG_ID='weather_dag' AIRFLOW_CTX_TASK_ID='transform_load_weather_data_to_S3' AIRFLOW_CTX_EXECUTION_DATE='2024-02-09T18:24:38.941675+00:00' AIRFLOW_CTX_TRY_NUMBER='3' AIRFLOW_CTX_DAG_RUN_ID='manual__2024-02-09T18:24:38.941675+00:00'
[2024-02-09T18:29:37.226+0000] {taskinstance.py:2698} ERROR - Task failed with exception
Traceback (most recent call last):
  File "/home/airflow/.local/lib/python3.8/site-packages/airflow/models/taskinstance.py", line 433, in _execute_task
    result = execute_callable(context=context, **execute_callable_kwargs)
  File "/home/airflow/.local/lib/python3.8/site-packages/airflow/operators/python.py", line 199, in execute
    return_value = self.execute_callable()
  File "/home/airflow/.local/lib/python3.8/site-packages/airflow/operators/python.py", line 216, in execute_callable
    return self.python_callable(*self.op_args, **self.op_kwargs)
  File "/opt/airflow/dags/Weather_dag.py", line 24, in transform_load_data
    r = requests.get(WEATHER_API_URL)
NameError: name 'requests' is not defined
[2024-02-09T18:29:37.242+0000] {taskinstance.py:1138} INFO - Marking task as FAILED. dag_id=weather_dag, task_id=transform_load_weather_data_to_S3, execution_date=20240209T182438, start_date=20240209T182936, end_date=20240209T182937
[2024-02-09T18:29:37.261+0000] {standard_task_runner.py:107} ERROR - Failed to execute job 22 for task transform_load_weather_data_to_S3 (name 'requests' is not defined; 53)
[2024-02-09T18:29:37.282+0000] {local_task_job_runner.py:234} INFO - Task exited with return code 1
[2024-02-09T18:29:37.310+0000] {taskinstance.py:3280} INFO - 0 downstream tasks scheduled from follow-on schedule check
