[2024-02-12T10:32:24.776+0000] {taskinstance.py:1956} INFO - Dependencies all met for dep_context=non-requeueable deps ti=<TaskInstance: test_redshift_dag.create_table manual__2024-02-12T10:26:51.819812+00:00 [queued]>
[2024-02-12T10:32:24.795+0000] {taskinstance.py:1956} INFO - Dependencies all met for dep_context=requeueable deps ti=<TaskInstance: test_redshift_dag.create_table manual__2024-02-12T10:26:51.819812+00:00 [queued]>
[2024-02-12T10:32:24.796+0000] {taskinstance.py:2170} INFO - Starting attempt 3 of 3
[2024-02-12T10:32:24.821+0000] {taskinstance.py:2191} INFO - Executing <Task(PostgresOperator): create_table> on 2024-02-12 10:26:51.819812+00:00
[2024-02-12T10:32:24.829+0000] {standard_task_runner.py:60} INFO - Started process 176 to run task
[2024-02-12T10:32:24.833+0000] {standard_task_runner.py:87} INFO - Running: ['***', 'tasks', 'run', 'test_redshift_dag', 'create_table', 'manual__2024-02-12T10:26:51.819812+00:00', '--job-id', '46', '--raw', '--subdir', 'DAGS_FOLDER/s3 _to_redshift.py', '--cfg-path', '/tmp/tmpyteeut0_']
[2024-02-12T10:32:24.838+0000] {standard_task_runner.py:88} INFO - Job 46: Subtask create_table
[2024-02-12T10:32:24.913+0000] {task_command.py:423} INFO - Running <TaskInstance: test_redshift_dag.create_table manual__2024-02-12T10:26:51.819812+00:00 [running]> on host f6c6a9bbd38e
[2024-02-12T10:32:25.006+0000] {taskinstance.py:2480} INFO - Exporting env vars: AIRFLOW_CTX_DAG_OWNER='stellar' AIRFLOW_CTX_DAG_ID='test_redshift_dag' AIRFLOW_CTX_TASK_ID='create_table' AIRFLOW_CTX_EXECUTION_DATE='2024-02-12T10:26:51.819812+00:00' AIRFLOW_CTX_TRY_NUMBER='3' AIRFLOW_CTX_DAG_RUN_ID='manual__2024-02-12T10:26:51.819812+00:00'
[2024-02-12T10:32:25.009+0000] {sql.py:276} INFO - Executing:  
                CREATE TABLE test.weather_demo_table (
                    "Time of Record" datetime,
                    City varchar(25),
                    Description varchar(25),
                    "Temperature (C)" float,
                    "Feels Like (C)" float,
                    "Minimun Temp (C)" float,
                    "Maximum Temp (C)" float,
                    Pressure integer,
                    Humidty integer,
                    "Wind Speed" float,
                    "Sunrise (Local Time)" datetime,
                    "Sunset (Local Time)" datetime
                )
    
[2024-02-12T10:32:25.021+0000] {base.py:83} INFO - Using connection ID 'redshift_default' for task execution.
[2024-02-12T10:32:25.035+0000] {base.py:83} INFO - Using connection ID 'redshift_default' for task execution.
[2024-02-12T10:33:07.097+0000] {taskinstance.py:2698} ERROR - Task failed with exception
Traceback (most recent call last):
  File "/home/airflow/.local/lib/python3.8/site-packages/airflow/models/taskinstance.py", line 433, in _execute_task
    result = execute_callable(context=context, **execute_callable_kwargs)
  File "/home/airflow/.local/lib/python3.8/site-packages/airflow/providers/common/sql/operators/sql.py", line 282, in execute
    output = hook.run(
  File "/home/airflow/.local/lib/python3.8/site-packages/airflow/providers/common/sql/hooks/sql.py", line 391, in run
    with closing(self.get_conn()) as conn:
  File "/home/airflow/.local/lib/python3.8/site-packages/airflow/providers/postgres/hooks/postgres.py", line 158, in get_conn
    self.conn = psycopg2.connect(**conn_args)
  File "/home/airflow/.local/lib/python3.8/site-packages/psycopg2/__init__.py", line 122, in connect
    conn = _connect(dsn, connection_factory=connection_factory, **kwasync)
psycopg2.OperationalError: connection to server at "redshift-cluster-1.cknvvpe46ntw.ap-southeast-1.redshift.amazonaws.com" (54.251.171.212), port 5439 failed: Connection refused
	Is the server running on that host and accepting TCP/IP connections?
connection to server at "redshift-cluster-1.cknvvpe46ntw.ap-southeast-1.redshift.amazonaws.com" (54.251.171.212), port 5439 failed: Connection refused
	Is the server running on that host and accepting TCP/IP connections?

[2024-02-12T10:33:07.117+0000] {taskinstance.py:1138} INFO - Marking task as FAILED. dag_id=test_redshift_dag, task_id=create_table, execution_date=20240212T102651, start_date=20240212T103224, end_date=20240212T103307
[2024-02-12T10:33:07.156+0000] {standard_task_runner.py:107} ERROR - Failed to execute job 46 for task create_table (connection to server at "redshift-cluster-1.cknvvpe46ntw.ap-southeast-1.redshift.amazonaws.com" (54.251.171.212), port 5439 failed: Connection refused
	Is the server running on that host and accepting TCP/IP connections?
connection to server at "redshift-cluster-1.cknvvpe46ntw.ap-southeast-1.redshift.amazonaws.com" (54.251.171.212), port 5439 failed: Connection refused
	Is the server running on that host and accepting TCP/IP connections?
; 176)
[2024-02-12T10:33:07.199+0000] {local_task_job_runner.py:234} INFO - Task exited with return code 1
[2024-02-12T10:33:07.219+0000] {taskinstance.py:3280} INFO - 0 downstream tasks scheduled from follow-on schedule check
