[2024-02-11T08:16:31.258+0000] {taskinstance.py:1956} INFO - Dependencies all met for dep_context=non-requeueable deps ti=<TaskInstance: test_redshift_dag.transfer_s3_to_redshift manual__2024-02-11T08:10:39.090060+00:00 [queued]>
[2024-02-11T08:16:31.270+0000] {taskinstance.py:1956} INFO - Dependencies all met for dep_context=requeueable deps ti=<TaskInstance: test_redshift_dag.transfer_s3_to_redshift manual__2024-02-11T08:10:39.090060+00:00 [queued]>
[2024-02-11T08:16:31.271+0000] {taskinstance.py:2170} INFO - Starting attempt 4 of 6
[2024-02-11T08:16:31.290+0000] {taskinstance.py:2191} INFO - Executing <Task(S3ToRedshiftOperator): transfer_s3_to_redshift> on 2024-02-11 08:10:39.090060+00:00
[2024-02-11T08:16:31.298+0000] {standard_task_runner.py:60} INFO - Started process 223 to run task
[2024-02-11T08:16:31.304+0000] {standard_task_runner.py:87} INFO - Running: ['***', 'tasks', 'run', 'test_redshift_dag', 'transfer_s3_to_redshift', 'manual__2024-02-11T08:10:39.090060+00:00', '--job-id', '11', '--raw', '--subdir', 'DAGS_FOLDER/s3 _to_redshift.py', '--cfg-path', '/tmp/tmpgjkcaetw']
[2024-02-11T08:16:31.309+0000] {standard_task_runner.py:88} INFO - Job 11: Subtask transfer_s3_to_redshift
[2024-02-11T08:16:31.395+0000] {task_command.py:423} INFO - Running <TaskInstance: test_redshift_dag.transfer_s3_to_redshift manual__2024-02-11T08:10:39.090060+00:00 [running]> on host 35f4ee28a87c
[2024-02-11T08:16:31.515+0000] {taskinstance.py:2480} INFO - Exporting env vars: AIRFLOW_CTX_DAG_OWNER='stellar' AIRFLOW_CTX_DAG_ID='test_redshift_dag' AIRFLOW_CTX_TASK_ID='transfer_s3_to_redshift' AIRFLOW_CTX_EXECUTION_DATE='2024-02-11T08:10:39.090060+00:00' AIRFLOW_CTX_TRY_NUMBER='4' AIRFLOW_CTX_DAG_RUN_ID='manual__2024-02-11T08:10:39.090060+00:00'
[2024-02-11T08:16:31.537+0000] {base.py:83} INFO - Using connection ID 's3_dev_conn' for task execution.
[2024-02-11T08:16:31.557+0000] {base.py:83} INFO - Using connection ID 's3_dev_conn' for task execution.
[2024-02-11T08:16:31.559+0000] {connection_wrapper.py:378} INFO - AWS Connection (conn_id='s3_dev_conn', conn_type='aws') credentials retrieved from login and password.
[2024-02-11T08:16:31.588+0000] {s3_to_redshift.py:192} INFO - Executing COPY command...
[2024-02-11T08:16:31.605+0000] {base.py:83} INFO - Using connection ID 'redshift_default' for task execution.
[2024-02-11T08:16:53.286+0000] {taskinstance.py:2698} ERROR - Task failed with exception
Traceback (most recent call last):
  File "/home/airflow/.local/lib/python3.8/site-packages/redshift_connector/core.py", line 626, in __init__
    self._usock.connect(hostport)
ConnectionRefusedError: [Errno 111] Connection refused

During handling of the above exception, another exception occurred:

Traceback (most recent call last):
  File "/home/airflow/.local/lib/python3.8/site-packages/airflow/models/taskinstance.py", line 433, in _execute_task
    result = execute_callable(context=context, **execute_callable_kwargs)
  File "/home/airflow/.local/lib/python3.8/site-packages/airflow/providers/amazon/aws/transfers/s3_to_redshift.py", line 196, in execute
    redshift_hook.run(sql, autocommit=self.autocommit)
  File "/home/airflow/.local/lib/python3.8/site-packages/airflow/providers/common/sql/hooks/sql.py", line 391, in run
    with closing(self.get_conn()) as conn:
  File "/home/airflow/.local/lib/python3.8/site-packages/airflow/providers/amazon/aws/hooks/redshift_sql.py", line 200, in get_conn
    return redshift_connector.connect(**conn_kwargs)
  File "/home/airflow/.local/lib/python3.8/site-packages/redshift_connector/__init__.py", line 376, in connect
    return Connection(
  File "/home/airflow/.local/lib/python3.8/site-packages/redshift_connector/core.py", line 689, in __init__
    raise InterfaceError("communication error", e)
redshift_connector.error.InterfaceError: ('communication error', ConnectionRefusedError(111, 'Connection refused'))
[2024-02-11T08:16:53.297+0000] {taskinstance.py:1138} INFO - Marking task as UP_FOR_RETRY. dag_id=test_redshift_dag, task_id=transfer_s3_to_redshift, execution_date=20240211T081039, start_date=20240211T081631, end_date=20240211T081653
[2024-02-11T08:16:53.319+0000] {standard_task_runner.py:107} ERROR - Failed to execute job 11 for task transfer_s3_to_redshift (('communication error', ConnectionRefusedError(111, 'Connection refused')); 223)
[2024-02-11T08:16:53.373+0000] {local_task_job_runner.py:234} INFO - Task exited with return code 1
[2024-02-11T08:16:53.395+0000] {taskinstance.py:3280} INFO - 0 downstream tasks scheduled from follow-on schedule check
