[2024-02-12T21:43:48.670+0000] {taskinstance.py:1956} INFO - Dependencies all met for dep_context=non-requeueable deps ti=<TaskInstance: weather_dag.create_snowflake_external_stage scheduled__2024-02-12T21:00:00+00:00 [queued]>
[2024-02-12T21:43:48.717+0000] {taskinstance.py:1956} INFO - Dependencies all met for dep_context=requeueable deps ti=<TaskInstance: weather_dag.create_snowflake_external_stage scheduled__2024-02-12T21:00:00+00:00 [queued]>
[2024-02-12T21:43:48.720+0000] {taskinstance.py:2170} INFO - Starting attempt 2 of 3
[2024-02-12T21:43:48.763+0000] {taskinstance.py:2191} INFO - Executing <Task(SnowflakeOperator): create_snowflake_external_stage> on 2024-02-12 21:00:00+00:00
[2024-02-12T21:43:48.776+0000] {standard_task_runner.py:60} INFO - Started process 56 to run task
[2024-02-12T21:43:48.782+0000] {standard_task_runner.py:87} INFO - Running: ['***', 'tasks', 'run', 'weather_dag', 'create_snowflake_external_stage', 'scheduled__2024-02-12T21:00:00+00:00', '--job-id', '62', '--raw', '--subdir', 'DAGS_FOLDER/Weather_dag.py', '--cfg-path', '/tmp/tmp7vc9z3pj']
[2024-02-12T21:43:48.786+0000] {standard_task_runner.py:88} INFO - Job 62: Subtask create_snowflake_external_stage
[2024-02-12T21:43:48.914+0000] {task_command.py:423} INFO - Running <TaskInstance: weather_dag.create_snowflake_external_stage scheduled__2024-02-12T21:00:00+00:00 [running]> on host 3bd3b2605e24
[2024-02-12T21:43:49.144+0000] {taskinstance.py:2480} INFO - Exporting env vars: AIRFLOW_CTX_DAG_OWNER='stellar' AIRFLOW_CTX_DAG_ID='weather_dag' AIRFLOW_CTX_TASK_ID='create_snowflake_external_stage' AIRFLOW_CTX_EXECUTION_DATE='2024-02-12T21:00:00+00:00' AIRFLOW_CTX_TRY_NUMBER='2' AIRFLOW_CTX_DAG_RUN_ID='scheduled__2024-02-12T21:00:00+00:00'
[2024-02-12T21:43:49.147+0000] {sql.py:276} INFO - Executing: 
                    CREATE OR REPLACE s3_stage
                        URL = "s3://bucket-weather-data/current_weather_data_portland_12022024213702.csv"
                        credentials=(aws_key_id="AKIAVRUVRXEM77SSYROY", aws_secret_key="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");
                
            
[2024-02-12T21:43:49.171+0000] {base.py:83} INFO - Using connection ID 'conn_id_snowflake' for task execution.
[2024-02-12T21:43:49.192+0000] {base.py:83} INFO - Using connection ID 'conn_id_snowflake' for task execution.
[2024-02-12T21:43:49.193+0000] {connection.py:370} INFO - Snowflake Connector for Python Version: 3.6.0, Python Version: 3.8.18, Platform: Linux-5.15.133.1-microsoft-standard-WSL2-x86_64-with-glibc2.34
[2024-02-12T21:43:49.195+0000] {connection.py:1171} INFO - This connection is in OCSP Fail Open Mode. TLS Certificates would be checked for validity and revocation status. Any other Certificate Revocation related exceptions or OCSP Responder failures would be disregarded in favor of connectivity.
[2024-02-12T21:43:49.750+0000] {cursor.py:1028} INFO - query: [ALTER SESSION SET autocommit=False]
[2024-02-12T21:43:49.849+0000] {cursor.py:1041} INFO - query execution done
[2024-02-12T21:43:49.850+0000] {cursor.py:1205} INFO - Number of results in first chunk: 1
[2024-02-12T21:43:49.851+0000] {sql.py:450} INFO - Running statement: CREATE OR REPLACE s3_stage
                        URL = "s3://bucket-weather-data/current_weather_data_portland_12022024213702.csv"
                        credentials=(aws_key_id="AKIAVRUVRXEM77SSYROY", aws_secret_key="6K0K3J/4qOYp3hPjFgDcayWYKoNNZF9DmVD581vs");, parameters: None
[2024-02-12T21:43:49.853+0000] {cursor.py:1028} INFO - query: [CREATE OR REPLACE s3_stage URL = "s3://bucket-weather-data/current_weather_data_...]
[2024-02-12T21:43:49.946+0000] {cursor.py:1041} INFO - query execution done
[2024-02-12T21:43:49.958+0000] {connection.py:718} INFO - closed
[2024-02-12T21:43:50.022+0000] {connection.py:724} INFO - No async queries seem to be running, deleting session
[2024-02-12T21:43:50.086+0000] {taskinstance.py:2698} ERROR - Task failed with exception
Traceback (most recent call last):
  File "/home/airflow/.local/lib/python3.8/site-packages/airflow/models/taskinstance.py", line 433, in _execute_task
    result = execute_callable(context=context, **execute_callable_kwargs)
  File "/home/airflow/.local/lib/python3.8/site-packages/airflow/providers/common/sql/operators/sql.py", line 282, in execute
    output = hook.run(
  File "/home/airflow/.local/lib/python3.8/site-packages/airflow/providers/snowflake/hooks/snowflake.py", line 388, in run
    self._run_command(cur, sql_statement, parameters)
  File "/home/airflow/.local/lib/python3.8/site-packages/airflow/providers/common/sql/hooks/sql.py", line 455, in _run_command
    cur.execute(sql_statement)
  File "/home/airflow/.local/lib/python3.8/site-packages/snowflake/connector/cursor.py", line 1132, in execute
    Error.errorhandler_wrapper(self.connection, self, error_class, errvalue)
  File "/home/airflow/.local/lib/python3.8/site-packages/snowflake/connector/errors.py", line 290, in errorhandler_wrapper
    handed_over = Error.hand_to_other_handler(
  File "/home/airflow/.local/lib/python3.8/site-packages/snowflake/connector/errors.py", line 345, in hand_to_other_handler
    cursor.errorhandler(connection, cursor, error_class, error_value)
  File "/home/airflow/.local/lib/python3.8/site-packages/snowflake/connector/errors.py", line 221, in default_errorhandler
    raise error_class(
snowflake.connector.errors.ProgrammingError: 001003 (42000): 01b24f37-3200-fe68-0007-a44e0001040e: SQL compilation error:
syntax error line 2 at position 28 unexpected '='.
[2024-02-12T21:43:50.100+0000] {taskinstance.py:1138} INFO - Marking task as UP_FOR_RETRY. dag_id=weather_dag, task_id=create_snowflake_external_stage, execution_date=20240212T210000, start_date=20240212T214348, end_date=20240212T214350
[2024-02-12T21:43:50.129+0000] {standard_task_runner.py:107} ERROR - Failed to execute job 62 for task create_snowflake_external_stage (001003 (42000): 01b24f37-3200-fe68-0007-a44e0001040e: SQL compilation error:
syntax error line 2 at position 28 unexpected '='.; 56)
[2024-02-12T21:43:50.160+0000] {local_task_job_runner.py:234} INFO - Task exited with return code 1
[2024-02-12T21:43:50.197+0000] {taskinstance.py:3280} INFO - 0 downstream tasks scheduled from follow-on schedule check
[2024-02-12T21:52:10.921+0000] {taskinstance.py:1956} INFO - Dependencies all met for dep_context=non-requeueable deps ti=<TaskInstance: weather_dag.create_snowflake_external_stage scheduled__2024-02-12T21:00:00+00:00 [queued]>
[2024-02-12T21:52:10.949+0000] {taskinstance.py:1956} INFO - Dependencies all met for dep_context=requeueable deps ti=<TaskInstance: weather_dag.create_snowflake_external_stage scheduled__2024-02-12T21:00:00+00:00 [queued]>
[2024-02-12T21:52:10.951+0000] {taskinstance.py:2170} INFO - Starting attempt 2 of 3
[2024-02-12T21:52:10.990+0000] {taskinstance.py:2191} INFO - Executing <Task(SnowflakeOperator): create_snowflake_external_stage> on 2024-02-12 21:00:00+00:00
[2024-02-12T21:52:10.999+0000] {standard_task_runner.py:60} INFO - Started process 140 to run task
[2024-02-12T21:52:11.007+0000] {standard_task_runner.py:87} INFO - Running: ['***', 'tasks', 'run', 'weather_dag', 'create_snowflake_external_stage', 'scheduled__2024-02-12T21:00:00+00:00', '--job-id', '84', '--raw', '--subdir', 'DAGS_FOLDER/Weather_dag.py', '--cfg-path', '/tmp/tmpqwjt09uu']
[2024-02-12T21:52:11.009+0000] {standard_task_runner.py:88} INFO - Job 84: Subtask create_snowflake_external_stage
[2024-02-12T21:52:11.104+0000] {task_command.py:423} INFO - Running <TaskInstance: weather_dag.create_snowflake_external_stage scheduled__2024-02-12T21:00:00+00:00 [running]> on host 3bd3b2605e24
[2024-02-12T21:52:11.297+0000] {taskinstance.py:2480} INFO - Exporting env vars: AIRFLOW_CTX_DAG_OWNER='stellar' AIRFLOW_CTX_DAG_ID='weather_dag' AIRFLOW_CTX_TASK_ID='create_snowflake_external_stage' AIRFLOW_CTX_EXECUTION_DATE='2024-02-12T21:00:00+00:00' AIRFLOW_CTX_TRY_NUMBER='2' AIRFLOW_CTX_DAG_RUN_ID='scheduled__2024-02-12T21:00:00+00:00'
[2024-02-12T21:52:11.299+0000] {sql.py:276} INFO - Executing: 
                    CREATE OR REPLACE s3_stage
                        URL = s3://bucket-weather-data/current_weather_data_portland_12022024214945.csv
                        credentials=(aws_key_id="AKIAVRUVRXEM77SSYROY" aws_secret_key="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");
                
            
[2024-02-12T21:52:11.319+0000] {base.py:83} INFO - Using connection ID 'conn_id_snowflake' for task execution.
[2024-02-12T21:52:11.332+0000] {base.py:83} INFO - Using connection ID 'conn_id_snowflake' for task execution.
[2024-02-12T21:52:11.334+0000] {connection.py:370} INFO - Snowflake Connector for Python Version: 3.6.0, Python Version: 3.8.18, Platform: Linux-5.15.133.1-microsoft-standard-WSL2-x86_64-with-glibc2.34
[2024-02-12T21:52:11.337+0000] {connection.py:1171} INFO - This connection is in OCSP Fail Open Mode. TLS Certificates would be checked for validity and revocation status. Any other Certificate Revocation related exceptions or OCSP Responder failures would be disregarded in favor of connectivity.
[2024-02-12T21:52:11.914+0000] {cursor.py:1028} INFO - query: [ALTER SESSION SET autocommit=False]
[2024-02-12T21:52:12.002+0000] {cursor.py:1041} INFO - query execution done
[2024-02-12T21:52:12.003+0000] {cursor.py:1205} INFO - Number of results in first chunk: 1
[2024-02-12T21:52:12.004+0000] {sql.py:450} INFO - Running statement: CREATE OR REPLACE s3_stage
                        URL = s3://bucket-weather-data/current_weather_data_portland_12022024214945.csv
                        credentials=(aws_key_id="AKIAVRUVRXEM77SSYROY" aws_secret_key="6K0K3J/4qOYp3hPjFgDcayWYKoNNZF9DmVD581vs");, parameters: None
[2024-02-12T21:52:12.005+0000] {cursor.py:1028} INFO - query: [CREATE OR REPLACE s3_stage URL = s3://bucket-weather-data/current_weather_data_p...]
[2024-02-12T21:52:12.114+0000] {cursor.py:1041} INFO - query execution done
[2024-02-12T21:52:12.128+0000] {connection.py:718} INFO - closed
[2024-02-12T21:52:12.192+0000] {connection.py:724} INFO - No async queries seem to be running, deleting session
[2024-02-12T21:52:12.253+0000] {taskinstance.py:2698} ERROR - Task failed with exception
Traceback (most recent call last):
  File "/home/airflow/.local/lib/python3.8/site-packages/airflow/models/taskinstance.py", line 433, in _execute_task
    result = execute_callable(context=context, **execute_callable_kwargs)
  File "/home/airflow/.local/lib/python3.8/site-packages/airflow/providers/common/sql/operators/sql.py", line 282, in execute
    output = hook.run(
  File "/home/airflow/.local/lib/python3.8/site-packages/airflow/providers/snowflake/hooks/snowflake.py", line 388, in run
    self._run_command(cur, sql_statement, parameters)
  File "/home/airflow/.local/lib/python3.8/site-packages/airflow/providers/common/sql/hooks/sql.py", line 455, in _run_command
    cur.execute(sql_statement)
  File "/home/airflow/.local/lib/python3.8/site-packages/snowflake/connector/cursor.py", line 1132, in execute
    Error.errorhandler_wrapper(self.connection, self, error_class, errvalue)
  File "/home/airflow/.local/lib/python3.8/site-packages/snowflake/connector/errors.py", line 290, in errorhandler_wrapper
    handed_over = Error.hand_to_other_handler(
  File "/home/airflow/.local/lib/python3.8/site-packages/snowflake/connector/errors.py", line 345, in hand_to_other_handler
    cursor.errorhandler(connection, cursor, error_class, error_value)
  File "/home/airflow/.local/lib/python3.8/site-packages/snowflake/connector/errors.py", line 221, in default_errorhandler
    raise error_class(
snowflake.connector.errors.ProgrammingError: 001003 (42000): 01b24f40-3200-fe5c-0007-a44e00011476: SQL compilation error:
syntax error line 2 at position 28 unexpected '='.
syntax error line 3 at position 71 unexpected 'aws_secret_key'.
syntax error line 3 at position 128 unexpected ')'.
[2024-02-12T21:52:12.265+0000] {taskinstance.py:1138} INFO - Marking task as UP_FOR_RETRY. dag_id=weather_dag, task_id=create_snowflake_external_stage, execution_date=20240212T210000, start_date=20240212T215210, end_date=20240212T215212
[2024-02-12T21:52:12.284+0000] {standard_task_runner.py:107} ERROR - Failed to execute job 84 for task create_snowflake_external_stage (001003 (42000): 01b24f40-3200-fe5c-0007-a44e00011476: SQL compilation error:
syntax error line 2 at position 28 unexpected '='.
syntax error line 3 at position 71 unexpected 'aws_secret_key'.
syntax error line 3 at position 128 unexpected ')'.; 140)
[2024-02-12T21:52:12.306+0000] {local_task_job_runner.py:234} INFO - Task exited with return code 1
[2024-02-12T21:52:12.362+0000] {taskinstance.py:3280} INFO - 0 downstream tasks scheduled from follow-on schedule check
