[2024-02-12T10:05:02.173+0000] {taskinstance.py:1956} INFO - Dependencies all met for dep_context=non-requeueable deps ti=<TaskInstance: weather_dag.transform_load_weather_data_to_S3 scheduled__2024-02-12T09:00:00+00:00 [queued]>
[2024-02-12T10:05:02.196+0000] {taskinstance.py:1956} INFO - Dependencies all met for dep_context=requeueable deps ti=<TaskInstance: weather_dag.transform_load_weather_data_to_S3 scheduled__2024-02-12T09:00:00+00:00 [queued]>
[2024-02-12T10:05:02.198+0000] {taskinstance.py:2170} INFO - Starting attempt 5 of 6
[2024-02-12T10:05:02.533+0000] {taskinstance.py:2191} INFO - Executing <Task(PythonOperator): transform_load_weather_data_to_S3> on 2024-02-12 09:00:00+00:00
[2024-02-12T10:05:02.559+0000] {standard_task_runner.py:60} INFO - Started process 58 to run task
[2024-02-12T10:05:02.566+0000] {standard_task_runner.py:87} INFO - Running: ['***', 'tasks', 'run', 'weather_dag', 'transform_load_weather_data_to_S3', 'scheduled__2024-02-12T09:00:00+00:00', '--job-id', '23', '--raw', '--subdir', 'DAGS_FOLDER/Weather_dag.py', '--cfg-path', '/tmp/tmpi3w58min']
[2024-02-12T10:05:02.569+0000] {standard_task_runner.py:88} INFO - Job 23: Subtask transform_load_weather_data_to_S3
[2024-02-12T10:05:02.771+0000] {task_command.py:423} INFO - Running <TaskInstance: weather_dag.transform_load_weather_data_to_S3 scheduled__2024-02-12T09:00:00+00:00 [running]> on host f6c6a9bbd38e
[2024-02-12T10:05:02.953+0000] {taskinstance.py:2480} INFO - Exporting env vars: AIRFLOW_CTX_DAG_OWNER='stellar' AIRFLOW_CTX_DAG_ID='weather_dag' AIRFLOW_CTX_TASK_ID='transform_load_weather_data_to_S3' AIRFLOW_CTX_EXECUTION_DATE='2024-02-12T09:00:00+00:00' AIRFLOW_CTX_TRY_NUMBER='5' AIRFLOW_CTX_DAG_RUN_ID='scheduled__2024-02-12T09:00:00+00:00'
[2024-02-12T10:05:03.229+0000] {taskinstance.py:2698} ERROR - Task failed with exception
Traceback (most recent call last):
  File "/home/airflow/.local/lib/python3.8/site-packages/fsspec/registry.py", line 236, in get_filesystem_class
    register_implementation(protocol, _import_class(bit["class"]))
  File "/home/airflow/.local/lib/python3.8/site-packages/fsspec/registry.py", line 271, in _import_class
    mod = importlib.import_module(mod)
  File "/usr/local/lib/python3.8/importlib/__init__.py", line 127, in import_module
    return _bootstrap._gcd_import(name[level:], package, level)
  File "<frozen importlib._bootstrap>", line 1014, in _gcd_import
  File "<frozen importlib._bootstrap>", line 991, in _find_and_load
  File "<frozen importlib._bootstrap>", line 973, in _find_and_load_unlocked
ModuleNotFoundError: No module named 's3fs'

The above exception was the direct cause of the following exception:

Traceback (most recent call last):
  File "/home/airflow/.local/lib/python3.8/site-packages/airflow/models/taskinstance.py", line 433, in _execute_task
    result = execute_callable(context=context, **execute_callable_kwargs)
  File "/home/airflow/.local/lib/python3.8/site-packages/airflow/operators/python.py", line 199, in execute
    return_value = self.execute_callable()
  File "/home/airflow/.local/lib/python3.8/site-packages/airflow/operators/python.py", line 216, in execute_callable
    return self.python_callable(*self.op_args, **self.op_kwargs)
  File "/opt/airflow/dags/Weather_dag.py", line 58, in transform_load_data
    df_data.to_csv(f"s3://bucket-weather-data/Bangkok/Data/{dt_string}.csv", index=False,)
  File "/home/airflow/.local/lib/python3.8/site-packages/pandas/core/generic.py", line 3772, in to_csv
    return DataFrameRenderer(formatter).to_csv(
  File "/home/airflow/.local/lib/python3.8/site-packages/pandas/io/formats/format.py", line 1186, in to_csv
    csv_formatter.save()
  File "/home/airflow/.local/lib/python3.8/site-packages/pandas/io/formats/csvs.py", line 240, in save
    with get_handle(
  File "/home/airflow/.local/lib/python3.8/site-packages/pandas/io/common.py", line 716, in get_handle
    ioargs = _get_filepath_or_buffer(
  File "/home/airflow/.local/lib/python3.8/site-packages/pandas/io/common.py", line 414, in _get_filepath_or_buffer
    file_obj = fsspec.open(
  File "/home/airflow/.local/lib/python3.8/site-packages/fsspec/core.py", line 459, in open
    out = open_files(
  File "/home/airflow/.local/lib/python3.8/site-packages/fsspec/core.py", line 283, in open_files
    fs, fs_token, paths = get_fs_token_paths(
  File "/home/airflow/.local/lib/python3.8/site-packages/fsspec/core.py", line 623, in get_fs_token_paths
    chain = _un_chain(urlpath0, storage_options or {})
  File "/home/airflow/.local/lib/python3.8/site-packages/fsspec/core.py", line 332, in _un_chain
    cls = get_filesystem_class(protocol)
  File "/home/airflow/.local/lib/python3.8/site-packages/fsspec/registry.py", line 238, in get_filesystem_class
    raise ImportError(bit["err"]) from e
ImportError: Install s3fs to access S3
[2024-02-12T10:05:03.259+0000] {taskinstance.py:1138} INFO - Marking task as UP_FOR_RETRY. dag_id=weather_dag, task_id=transform_load_weather_data_to_S3, execution_date=20240212T090000, start_date=20240212T100502, end_date=20240212T100503
[2024-02-12T10:05:03.292+0000] {standard_task_runner.py:107} ERROR - Failed to execute job 23 for task transform_load_weather_data_to_S3 (Install s3fs to access S3; 58)
[2024-02-12T10:05:03.348+0000] {local_task_job_runner.py:234} INFO - Task exited with return code 1
[2024-02-12T10:05:03.382+0000] {taskinstance.py:3280} INFO - 0 downstream tasks scheduled from follow-on schedule check
